<sdf version="1.7">
  <world name="sim_world">
    <physics name="10ms" type="ode">
      <max_step_size>0.01</max_step_size>
      <real_time_factor>1.0</real_time_factor>
    </physics>
    <plugin filename="libignition-gazebo-physics-system.so" name="ignition::gazebo::systems::Physics">
    </plugin>
    <plugin filename="libignition-gazebo-user-commands-system.so" name="ignition::gazebo::systems::UserCommands">
    </plugin>
    <plugin filename="libignition-gazebo-scene-broadcaster-system.so" name="ignition::gazebo::systems::SceneBroadcaster">
    </plugin>
    <scene>
      <ambient>1 1 1</ambient>
      <background>0.8 0.8 0.8</background>
      <grid>false</grid>
    </scene>
    <gui fullscreen="0">
      <window>
        <width>1000</width>
        <height>845</height>
        <style material_theme="Light" material_primary="DeepOrange" material_accent="LightBlue" toolbar_color_light="#f3f3f3" toolbar_text_color_light="#111111" toolbar_color_dark="#414141" toolbar_text_color_dark="#f3f3f3" plugin_toolbar_color_light="#bbdefb" plugin_toolbar_text_color_light="#111111" plugin_toolbar_color_dark="#607d8b" plugin_toolbar_text_color_dark="#eeeeee" />
        <menus>
          <drawer default="false">
          </drawer>
        </menus>
      </window>
      <plugin filename="GzScene3D" name="3D View">
        <ignition-gui>
          <title>3D View</title>
          <property type="bool" key="showTitleBar">false</property>
          <property type="string" key="state">docked</property>
        </ignition-gui>
        <engine>ogre2</engine>
        <scene>scene</scene>
        <ambient_light>0.4 0.4 0.4</ambient_light>
        <background_color>0.8 0.8 0.8</background_color>
        <camera_pose>77.81111478686158 -133.19940772432875 10 0 0.6 1.57</camera_pose>
      </plugin>
      <plugin filename="WorldControl" name="World control">
        <ignition-gui>
          <title>World control</title>
          <property type="bool" key="showTitleBar">false</property>
          <property type="bool" key="resizable">false</property>
          <property type="double" key="height">72</property>
          <property type="double" key="width">121</property>
          <property type="double" key="z">1</property>
          <property type="string" key="state">floating</property>
          <anchors target="3D View">
            <line own="left" target="left" />
            <line own="bottom" target="bottom" />
          </anchors>
        </ignition-gui>
        <play_pause>true</play_pause>
        <step>true</step>
        <start_paused>true</start_paused>
      </plugin>
      <plugin filename="WorldStats" name="World stats">
        <ignition-gui>
          <title>World stats</title>
          <property type="bool" key="showTitleBar">false</property>
          <property type="bool" key="resizable">false</property>
          <property type="double" key="height">110</property>
          <property type="double" key="width">290</property>
          <property type="double" key="z">1</property>
          <property type="string" key="state">floating</property>
          <anchors target="3D View">
            <line own="right" target="right" />
            <line own="bottom" target="bottom" />
          </anchors>
        </ignition-gui>
        <sim_time>true</sim_time>
        <real_time>true</real_time>
        <real_time_factor>true</real_time_factor>
        <iterations>true</iterations>
      </plugin>
      <plugin filename="TransformControl" name="Transform control">
        <ignition-gui>
          <title>Transform control</title>
          <anchors target="3D View">
            <line own="left" target="left" />
            <line own="top" target="top" />
          </anchors>
          <property key="resizable" type="bool">false</property>
          <property key="width" type="double">230</property>
          <property key="height" type="double">50</property>
          <property key="state" type="string">floating</property>
          <property key="showTitleBar" type="bool">false</property>
          <property key="cardBackground" type="string">#666666</property>
        </ignition-gui>
      </plugin>
      <plugin filename="Shapes" name="Shapes">
        <ignition-gui>
          <anchors target="Transform control">
            <line own="left" target="right" />
            <line own="top" target="top" />
          </anchors>
          <property key="resizable" type="bool">false</property>
          <property key="width" type="double">200</property>
          <property key="height" type="double">50</property>
          <property key="state" type="string">floating</property>
          <property key="showTitleBar" type="bool">false</property>
          <property key="cardBackground" type="string">#666666</property>
        </ignition-gui>
      </plugin>
      <plugin filename="ComponentInspector" name="Component inspector">
        <ignition-gui>
          <property type="bool" key="showTitleBar">false</property>
          <property type="string" key="state">docked</property>
        </ignition-gui>
      </plugin>
      <plugin filename="EntityTree" name="Entity tree">
        <ignition-gui>
          <property type="bool" key="showTitleBar">false</property>
          <property type="string" key="state">docked</property>
        </ignition-gui>
      </plugin>
      <plugin filename="toggle_charging" name="toggle_charging" />
      <plugin name="toggle_floors" filename="toggle_floors">
        <floor name="floor1" model_name="map_elettra_floor1">
          <model name="OpenRobotics/AdjTable" />
          <model name="OpenRobotics/AdjTable_2" />
          <model name="OpenRobotics/AdjTable_3" />
          <model name="LIFT1_1_door" />
        </floor>
        <floor name="floor2" model_name="map_elettra_floor2">
          <model name="LIFT1_2_door" />
        </floor>
      </plugin>
    </gui>
    <light type="directional" name="sun">
      <cast_shadows>true</cast_shadows>
      <pose>0 0 10 0 0 0</pose>
      <diffuse>1 1 1 1</diffuse>
      <specular>0.2 0.2 0.2 1</specular>
      <attenuation>
        <range>1000</range>
        <constant>0.09</constant>
        <linear>0.001</linear>
        <quadratic>0.001</quadratic>
      </attenuation>
      <direction>-0.5 0.1 -0.9</direction>
    </light>
    <include>
      <name>OpenRobotics/AdjTable</name>
      <uri>model://AdjTable</uri>
      <pose>63.30745697718877 -104.40482018957937 1.0 0 0 1.5708</pose>
      <static>True</static>
    </include>
    <include>
      <name>OpenRobotics/AdjTable_2</name>
      <uri>model://AdjTable</uri>
      <pose>81.73017214731642 -91.24332485122451 1.0 0 0 1.5708</pose>
      <static>True</static>
    </include>
    <include>
      <name>OpenRobotics/AdjTable_3</name>
      <uri>model://AdjTable</uri>
      <pose>81.93992726225446 -89.39711948738902 1.0 0 0 1.5708</pose>
      <static>True</static>
    </include>
    <model name="LIFT1_1_door">
      <pose>56.89277169678835 -116.53908602267393 1.0 0 0 2.9216930009316164</pose>
      <link name="right">
        <pose>0.48630591218750446 0 1.11 0 0 0</pose>
        <visual name="right_visual">
          <geometry>
            <box>
              <size>0.9626118243750089 0.03 2.2</size>
            </box>
          </geometry>
          <material>
            <ambient>0.5 0.25 0 0.6</ambient>
            <diffuse>0.5 0.25 0 0.6</diffuse>
            <pbr>
              <metal>
                <metalness>0.0</metalness>
              </metal>
            </pbr>
          </material>
        </visual>
        <collision name="right_collision">
          <geometry>
            <box>
              <size>0.9626118243750089 0.03 2.2</size>
            </box>
          </geometry>
          <surface>
            <contact>
              <collide_bitmask>0x02</collide_bitmask>
            </contact>
          </surface>
        </collision>
        <inertial>
          <mass>50.0</mass>
          <inertia>
            <ixx>20.17041666666667</ixx>
            <iyy>24.02758968511077</iyy>
            <izz>3.864673018444096</izz>
          </inertia>
        </inertial>
      </link>
      <joint name="right_joint" type="prismatic">
        <parent>world</parent>
        <child>right</child>
        <axis>
          <xyz>1 0 0</xyz>
          <limit>
            <lower>0.0</lower>
            <upper>0.9726118243750089</upper>
            <effort>500.0</effort>
          </limit>
        </axis>
      </joint>
      <link name="left">
        <pose>-0.48630591218750446 0 1.11 0 0 0</pose>
        <visual name="left_visual">
          <geometry>
            <box>
              <size>0.9626118243750089 0.03 2.2</size>
            </box>
          </geometry>
          <material>
            <ambient>0.5 0.25 0 0.6</ambient>
            <diffuse>0.5 0.25 0 0.6</diffuse>
            <pbr>
              <metal>
                <metalness>0.0</metalness>
              </metal>
            </pbr>
          </material>
        </visual>
        <collision name="left_collision">
          <geometry>
            <box>
              <size>0.9626118243750089 0.03 2.2</size>
            </box>
          </geometry>
          <surface>
            <contact>
              <collide_bitmask>0x02</collide_bitmask>
            </contact>
          </surface>
        </collision>
        <inertial>
          <mass>50.0</mass>
          <inertia>
            <ixx>20.17041666666667</ixx>
            <iyy>24.02758968511077</iyy>
            <izz>3.864673018444096</izz>
          </inertia>
        </inertial>
      </link>
      <joint name="left_joint" type="prismatic">
        <parent>world</parent>
        <child>left</child>
        <axis>
          <xyz>1 0 0</xyz>
          <limit>
            <lower>-0.9726118243750089</lower>
            <upper>0.0</upper>
            <effort>500.0</effort>
          </limit>
        </axis>
      </joint>
      <plugin name="door" filename="libdoor.so">
        <v_max_door>0.2</v_max_door>
        <a_max_door>0.2</a_max_door>
        <a_nom_door>0.08</a_nom_door>
        <dx_min_door>0.001</dx_min_door>
        <f_max_door>100.0</f_max_door>
        <door name="LIFT1_1_door" type="DoubleSlidingDoor" left_joint_name="left_joint" right_joint_name="right_joint" />
      </plugin>
    </model>
    <include>
      <name>map_elettra_floor1</name>
      <uri>model://map_elettra_floor1</uri>
      <pose>0 0 1.0 0 0 0</pose>
    </include>
    <model name="LIFT1_2_door">
      <pose>757.806 -1550.4175 2.0 0 0 2.8198548913336587</pose>
      <link name="right">
        <pose>6.180118288714222 0 1.11 0 0 0</pose>
        <visual name="right_visual">
          <geometry>
            <box>
              <size>12.350236577428443 0.03 2.2</size>
            </box>
          </geometry>
          <material>
            <ambient>0.5 0.25 0 0.6</ambient>
            <diffuse>0.5 0.25 0 0.6</diffuse>
            <pbr>
              <metal>
                <metalness>0.0</metalness>
              </metal>
            </pbr>
          </material>
        </visual>
        <collision name="right_collision">
          <geometry>
            <box>
              <size>12.350236577428443 0.03 2.2</size>
            </box>
          </geometry>
          <surface>
            <contact>
              <collide_bitmask>0x02</collide_bitmask>
            </contact>
          </surface>
        </collision>
        <inertial>
          <mass>50.0</mass>
          <inertia>
            <ixx>20.17041666666667</ixx>
            <iyy>655.701431326881</iyy>
            <izz>635.5385146602143</izz>
          </inertia>
        </inertial>
      </link>
      <joint name="right_joint" type="prismatic">
        <parent>world</parent>
        <child>right</child>
        <axis>
          <xyz>1 0 0</xyz>
          <limit>
            <lower>0.0</lower>
            <upper>12.360236577428443</upper>
            <effort>500.0</effort>
          </limit>
        </axis>
      </joint>
      <link name="left">
        <pose>-6.180118288714222 0 1.11 0 0 0</pose>
        <visual name="left_visual">
          <geometry>
            <box>
              <size>12.350236577428443 0.03 2.2</size>
            </box>
          </geometry>
          <material>
            <ambient>0.5 0.25 0 0.6</ambient>
            <diffuse>0.5 0.25 0 0.6</diffuse>
            <pbr>
              <metal>
                <metalness>0.0</metalness>
              </metal>
            </pbr>
          </material>
        </visual>
        <collision name="left_collision">
          <geometry>
            <box>
              <size>12.350236577428443 0.03 2.2</size>
            </box>
          </geometry>
          <surface>
            <contact>
              <collide_bitmask>0x02</collide_bitmask>
            </contact>
          </surface>
        </collision>
        <inertial>
          <mass>50.0</mass>
          <inertia>
            <ixx>20.17041666666667</ixx>
            <iyy>655.701431326881</iyy>
            <izz>635.5385146602143</izz>
          </inertia>
        </inertial>
      </link>
      <joint name="left_joint" type="prismatic">
        <parent>world</parent>
        <child>left</child>
        <axis>
          <xyz>1 0 0</xyz>
          <limit>
            <lower>-12.360236577428443</lower>
            <upper>0.0</upper>
            <effort>500.0</effort>
          </limit>
        </axis>
      </joint>
      <plugin name="door" filename="libdoor.so">
        <v_max_door>0.2</v_max_door>
        <a_max_door>0.2</a_max_door>
        <a_nom_door>0.08</a_nom_door>
        <dx_min_door>0.001</dx_min_door>
        <f_max_door>100.0</f_max_door>
        <door name="LIFT1_2_door" type="DoubleSlidingDoor" left_joint_name="left_joint" right_joint_name="right_joint" />
      </plugin>
    </model>
    <include>
      <name>map_elettra_floor2</name>
      <uri>model://map_elettra_floor2</uri>
      <pose>0 0 2.0 0 0 0</pose>
    </include>
    <rmf_charger_waypoints name="charger_waypoints" />
  </world>
</sdf>
